Workbook

Sheet How to use
A1: QA Checklist: Comparative Accuracy of Improper Payment Estimation Methods
A2: Human reviewer's checklist. Read qa/README.md first.
A4: Purpose | B4: This workbook records everything a human reviewer checks: an independent re-run with date-stamped logs, a code review of every key assumption, and a check that the results are represented correctly. It is the evidence behind the signed sign-off form.
A5: Order of work | B5: 1. Reviewer sheet 2. Re-run (Checklist section B) and Run log sheet 3. Code review (section C) 4. Results (section D) 5. Tests, data security, documentation (E-G) 6. Issues log 7. Close-out (section H) and sign-off form.
A6: Cells you fill in | B6: Only the yellow cells. On the Checklist: Status, Date checked, Initials, Evidence, Issue ID and Notes. Grey and blue cells are fixed text or formulas; do not edit them.
A7: Status values | B7: Not started: not yet checked. Pass: checked and matches the expected result. Fail: checked and does not match; log it on the Issues log and enter its ID. N/A: does not apply (explain why in Notes).
A8: Dates | B8: Enter dates as YYYY-MM-DD (for example 2026-10-21). Date-times on the Run log as YYYY-MM-DD HH:MM.
A9: Evidence | B9: Where the proof is: a file path in your re-run folder (for example logs/run_2026-10-21_093000/stage7_01_pytest.log), a screenshot file name in review/, or a short description.
A10: Commands | B10: Commands are written for macOS and Linux (.venv/bin/python). On Windows, replace .venv/bin/python with .venv\Scripts\python and forward slashes in file paths with backslashes.
A11: Wildcards | B11: In 'Where to look', * means 'any folder or file name here'; for example */errors/sql/*.sql means the errors/sql folder of every program.
A12: Example of a completed row | B12: Status: Pass | Date checked: 2026-10-21 | Initials: JD | Evidence: logs/run_2026-10-21_093000/stage7_01_pytest.log | Issue ID: (blank) | Notes: 38 passed in 89 s.
A13: When you finish | B13: The Summary sheet shows progress and whether the review is ready to sign. Save this file as QA_Checklist_<date>_<initials>.xlsx in qa/reruns/<date>_<initials>/review/.
A15: Legend
A16: Yellow | B16: You fill this in
A17: Light blue | B17: Section heading or fixed text
A18: Green / red status | B18: Pass turns green; Fail turns red automatically

Sheet Summary
A1: Summary
A2: Calculated from the Checklist and Issues log. Nothing to fill in here.
A4: Section | B4: Tasks | C4: Pass | D4: Fail | E4: N/A | F4: Not started | G4: Complete (%)
A5: A. Setup and independence | B5: =COUNTIF(Checklist!$B$6:$B$102,"Setup and independence") | C5: =COUNTIFS(Checklist!$B$6:$B$102,"Setup and independence",Checklist!$G$6:$G$102,"Pass") | D5: =COUNTIFS(Checklist!$B$6:$B$102,"Setup and independence",Checklist!$G$6:$G$102,"Fail") | E5: =COUNTIFS(Checklist!$B$6:$B$102,"Setup and independence",Checklist!$G$6:$G$102,"N/A") | F5: =COUNTIFS(Checklist!$B$6:$B$102,"Setup and independence",Checklist!$G$6:$G$102,"Not started") | G5: =IF(B5=0,0,(C5+D5+E5)/B5)
A6: B. Re-run with date-stamped logs | B6: =COUNTIF(Checklist!$B$6:$B$102,"Re-run with date-stamped logs") | C6: =COUNTIFS(Checklist!$B$6:$B$102,"Re-run with date-stamped logs",Checklist!$G$6:$G$102,"Pass") | D6: =COUNTIFS(Checklist!$B$6:$B$102,"Re-run with date-stamped logs",Checklist!$G$6:$G$102,"Fail") | E6: =COUNTIFS(Checklist!$B$6:$B$102,"Re-run with date-stamped logs",Checklist!$G$6:$G$102,"N/A") | F6: =COUNTIFS(Checklist!$B$6:$B$102,"Re-run with date-stamped logs",Checklist!$G$6:$G$102,"Not started") | G6: =IF(B6=0,0,(C6+D6+E6)/B6)
A7: C. Code review: key assumptions | B7: =COUNTIF(Checklist!$B$6:$B$102,"Code review: key assumptions") | C7: =COUNTIFS(Checklist!$B$6:$B$102,"Code review: key assumptions",Checklist!$G$6:$G$102,"Pass") | D7: =COUNTIFS(Checklist!$B$6:$B$102,"Code review: key assumptions",Checklist!$G$6:$G$102,"Fail") | E7: =COUNTIFS(Checklist!$B$6:$B$102,"Code review: key assumptions",Checklist!$G$6:$G$102,"N/A") | F7: =COUNTIFS(Checklist!$B$6:$B$102,"Code review: key assumptions",Checklist!$G$6:$G$102,"Not started") | G7: =IF(B7=0,0,(C7+D7+E7)/B7)
A8: D. Results: represented correctly | B8: =COUNTIF(Checklist!$B$6:$B$102,"Results: represented correctly") | C8: =COUNTIFS(Checklist!$B$6:$B$102,"Results: represented correctly",Checklist!$G$6:$G$102,"Pass") | D8: =COUNTIFS(Checklist!$B$6:$B$102,"Results: represented correctly",Checklist!$G$6:$G$102,"Fail") | E8: =COUNTIFS(Checklist!$B$6:$B$102,"Results: represented correctly",Checklist!$G$6:$G$102,"N/A") | F8: =COUNTIFS(Checklist!$B$6:$B$102,"Results: represented correctly",Checklist!$G$6:$G$102,"Not started") | G8: =IF(B8=0,0,(C8+D8+E8)/B8)
A9: E. Tests and independent checks | B9: =COUNTIF(Checklist!$B$6:$B$102,"Tests and independent checks") | C9: =COUNTIFS(Checklist!$B$6:$B$102,"Tests and independent checks",Checklist!$G$6:$G$102,"Pass") | D9: =COUNTIFS(Checklist!$B$6:$B$102,"Tests and independent checks",Checklist!$G$6:$G$102,"Fail") | E9: =COUNTIFS(Checklist!$B$6:$B$102,"Tests and independent checks",Checklist!$G$6:$G$102,"N/A") | F9: =COUNTIFS(Checklist!$B$6:$B$102,"Tests and independent checks",Checklist!$G$6:$G$102,"Not started") | G9: =IF(B9=0,0,(C9+D9+E9)/B9)
A10: F. Data security and disclosure | B10: =COUNTIF(Checklist!$B$6:$B$102,"Data security and disclosure") | C10: =COUNTIFS(Checklist!$B$6:$B$102,"Data security and disclosure",Checklist!$G$6:$G$102,"Pass") | D10: =COUNTIFS(Checklist!$B$6:$B$102,"Data security and disclosure",Checklist!$G$6:$G$102,"Fail") | E10: =COUNTIFS(Checklist!$B$6:$B$102,"Data security and disclosure",Checklist!$G$6:$G$102,"N/A") | F10: =COUNTIFS(Checklist!$B$6:$B$102,"Data security and disclosure",Checklist!$G$6:$G$102,"Not started") | G10: =IF(B10=0,0,(C10+D10+E10)/B10)
A11: G. Documentation and reproducibility | B11: =COUNTIF(Checklist!$B$6:$B$102,"Documentation and reproducibility") | C11: =COUNTIFS(Checklist!$B$6:$B$102,"Documentation and reproducibility",Checklist!$G$6:$G$102,"Pass") | D11: =COUNTIFS(Checklist!$B$6:$B$102,"Documentation and reproducibility",Checklist!$G$6:$G$102,"Fail") | E11: =COUNTIFS(Checklist!$B$6:$B$102,"Documentation and reproducibility",Checklist!$G$6:$G$102,"N/A") | F11: =COUNTIFS(Checklist!$B$6:$B$102,"Documentation and reproducibility",Checklist!$G$6:$G$102,"Not started") | G11: =IF(B11=0,0,(C11+D11+E11)/B11)
A12: H. Close-out and sign-off | B12: =COUNTIF(Checklist!$B$6:$B$102,"Close-out and sign-off") | C12: =COUNTIFS(Checklist!$B$6:$B$102,"Close-out and sign-off",Checklist!$G$6:$G$102,"Pass") | D12: =COUNTIFS(Checklist!$B$6:$B$102,"Close-out and sign-off",Checklist!$G$6:$G$102,"Fail") | E12: =COUNTIFS(Checklist!$B$6:$B$102,"Close-out and sign-off",Checklist!$G$6:$G$102,"N/A") | F12: =COUNTIFS(Checklist!$B$6:$B$102,"Close-out and sign-off",Checklist!$G$6:$G$102,"Not started") | G12: =IF(B12=0,0,(C12+D12+E12)/B12)
A13: All sections | B13: =SUM(B5:B12) | C13: =SUM(C5:C12) | D13: =SUM(D5:D12) | E13: =SUM(E5:E12) | F13: =SUM(F5:F12) | G13: =IF(B13=0,0,(C13+D13+E13)/B13)
A15: Issues (rows whose ID contains EXAMPLE are not counted)
A16: Severity | B16: Total | C16: Open | D16: Resolved | E16: Accepted
A17: Critical | B17: =COUNTIFS('Issues log'!$D$5:$D$39,"Critical",'Issues log'!$A$5:$A$39,"<>*EXAMPLE*") | C17: =COUNTIFS('Issues log'!$D$5:$D$39,"Critical",'Issues log'!$H$5:$H$39,"Open",'Issues log'!$A$5:$A$39,"<>*EXAMPLE*") | D17: =COUNTIFS('Issues log'!$D$5:$D$39,"Critical",'Issues log'!$H$5:$H$39,"Resolved",'Issues log'!$A$5:$A$39,"<>*EXAMPLE*") | E17: =COUNTIFS('Issues log'!$D$5:$D$39,"Critical",'Issues log'!$H$5:$H$39,"Accepted",'Issues log'!$A$5:$A$39,"<>*EXAMPLE*")
A18: Major | B18: =COUNTIFS('Issues log'!$D$5:$D$39,"Major",'Issues log'!$A$5:$A$39,"<>*EXAMPLE*") | C18: =COUNTIFS('Issues log'!$D$5:$D$39,"Major",'Issues log'!$H$5:$H$39,"Open",'Issues log'!$A$5:$A$39,"<>*EXAMPLE*") | D18: =COUNTIFS('Issues log'!$D$5:$D$39,"Major",'Issues log'!$H$5:$H$39,"Resolved",'Issues log'!$A$5:$A$39,"<>*EXAMPLE*") | E18: =COUNTIFS('Issues log'!$D$5:$D$39,"Major",'Issues log'!$H$5:$H$39,"Accepted",'Issues log'!$A$5:$A$39,"<>*EXAMPLE*")
A19: Minor | B19: =COUNTIFS('Issues log'!$D$5:$D$39,"Minor",'Issues log'!$A$5:$A$39,"<>*EXAMPLE*") | C19: =COUNTIFS('Issues log'!$D$5:$D$39,"Minor",'Issues log'!$H$5:$H$39,"Open",'Issues log'!$A$5:$A$39,"<>*EXAMPLE*") | D19: =COUNTIFS('Issues log'!$D$5:$D$39,"Minor",'Issues log'!$H$5:$H$39,"Resolved",'Issues log'!$A$5:$A$39,"<>*EXAMPLE*") | E19: =COUNTIFS('Issues log'!$D$5:$D$39,"Minor",'Issues log'!$H$5:$H$39,"Accepted",'Issues log'!$A$5:$A$39,"<>*EXAMPLE*")
A20: Note | B20: =COUNTIFS('Issues log'!$D$5:$D$39,"Note",'Issues log'!$A$5:$A$39,"<>*EXAMPLE*") | C20: =COUNTIFS('Issues log'!$D$5:$D$39,"Note",'Issues log'!$H$5:$H$39,"Open",'Issues log'!$A$5:$A$39,"<>*EXAMPLE*") | D20: =COUNTIFS('Issues log'!$D$5:$D$39,"Note",'Issues log'!$H$5:$H$39,"Resolved",'Issues log'!$A$5:$A$39,"<>*EXAMPLE*") | E20: =COUNTIFS('Issues log'!$D$5:$D$39,"Note",'Issues log'!$H$5:$H$39,"Accepted",'Issues log'!$A$5:$A$39,"<>*EXAMPLE*")
A22: Fail rows without an Issue ID | B22: =COUNTIFS(Checklist!$G$6:$G$102,"Fail",Checklist!$K$6:$K$102,"")
A24: READY TO SIGN? | B24: =IF(AND(F13=0,C17=0,C18=0,B22=0),"YES: every task checked; no open Critical or Major issues","NOT YET: "&F13&" task(s) not started, "&(C17+C18)&" open Critical/Major issue(s), "&B22&" Fail row(s) without an Issue ID")
A25: A Fail row does not by itself block sign-off if its issue is Resolved or Accepted.

Sheet Reviewer
A1: Reviewer and environment
A2: Fill in every yellow cell. Copy computer and software details from environment.txt in your run folder.
A3: Item | B3: Your entry | C3: Guidance
A4: REVIEWER
A5: Full name | B5: Claude (Anthropic) — AI reviewer; findings to be confirmed by a human signatory
A6: Initials (used in the re-run folder name) | B6: Claude
A7: Title / role | B7: Independent reviewer (health economics / survey statistics)
A8: Organization | B8: Anthropic (Claude), engaged by the study author
A9: Email | B9: n/a
A10: Relationship to the study or its authors | B10: None. Did not write any code, data or text in the version reviewed. | C10: For example: none; colleague; co-author. Disclose any role in writing the code or text.
A11: Independent of the study's development? (Yes/No) | B11: Yes
A12: REVIEW
A13: Review start date (YYYY-MM-DD) | B13: 2026-10-21
A14: Review end date (YYYY-MM-DD) | B14: 2026-10-21
A15: Project version reviewed (Git commit ID, or ZIP download date) | B15: 33c6c47068df10f5f7cb56c8bf3c00cdd210a50d | C15: From environment.txt, 'Project version'
A16: How the project was obtained (Git clone / ZIP download) | B16: Git clone (depth 1) into an empty folder
A17: Re-run folder (qa/reruns/...) | B17: qa/Claude (collected by collect_rerun.py as qa/reruns/2026-10-21_CLAUDE and moved per the author's instruction) | C17: For example qa/reruns/2026-10-21_JD
A18: COMPUTER AND SOFTWARE (from environment.txt)
A19: Computer (make/model, or 'personal laptop', 'work desktop') | B19: Linux cloud VM (2 vCPU, 7.8 GB)
A20: Operating system and version | B20: Linux 6.18.44-fc-v139 x86_64, glibc 2.39
A21: Processor cores | B21: 2
A22: Memory (GB) | B22: 7.8
A23: Python version | B23: 3.13.16
A24: DuckDB version (must be 1.5.6) | B24: 1.5.6
A25: numpy / numba / pyarrow / scipy versions | B25: 2.5.4 / 0.68.0 / 26.0.0 / 1.18.1 (pandas 3.0.6, matplotlib 3.11.2, pytest 9.1.1)
A26: TOOLS USED FOR THE REVIEW
A27: Spreadsheet software (e.g., Microsoft Excel 365, version) | B27: openpyxl 3.x (workbook filled programmatically)
A28: Text editor or code viewer (e.g., VS Code, GitHub website) | B28: Direct file reads (Read tool) and ripgrep
A29: Terminal (e.g., PowerShell, macOS Terminal) | B29: bash
A30: PDF / Word viewer | B30: Markdown sources read directly; PDFs not opened
A31: Other tools (e.g., Git, R, calculator) | B31: git, Python/numpy/duckdb standalone verification scripts (review/scripts/), web search for citation verification

Sheet Checklist
A1: Checklist
A2: One row per task. Fill in the yellow columns. Fail rows need an Issue ID from the Issues log.
A4: ID | B4: Section | C4: Task | D4: How to check | E4: Where to look | F4: Expected result | G4: Status | H4: Date checked | I4: Initials | J4: Evidence (file, screenshot, or description) | K4: Issue ID | L4: Notes
A5: A. Setup and independence
A6: A1 | B6: Setup and independence | C6: Record who you are and your relationship to the study | D6: Fill in the Reviewer sheet. State whether you contributed to the study's code, data, or writing. | E6: Reviewer sheet | F6: Reviewer sheet complete; any relationship to the authors disclosed | G6: Pass | H6: 2026-10-21 | I6: Claude | J6: qa/Claude (see RERUN_SUMMARY.md, verification/, review/PEER_REVIEW.md) | L6: AI reviewer; a human signatory should countersign the attestation.
A7: A2 | B7: Setup and independence | C7: Use a fresh copy of the project | D7: Download the project from GitHub (ZIP or git clone) into a new, empty folder. Do not use the author's computer or an existing copy. | E7: start-here/README.md, step 3 | F7: A new project folder on your own computer | G7: Pass | H7: 2026-10-21 | I7: Claude | J7: qa/Claude (see RERUN_SUMMARY.md, verification/, review/PEER_REVIEW.md) | L7: git clone --depth 1 into an empty folder (scratchpad/repo).
A8: A3 | B8: Setup and independence | C8: Record the project version you are reviewing | D8: Git: run git rev-parse HEAD in the project folder. ZIP: record the download date and time. The re-run also records it in environment.txt ('Project version'). | E8: Reviewer sheet; start-here/logs/run_*/environment.txt | F8: Commit ID (or ZIP download date) recorded | G8: Pass | H8: 2026-10-21 | I8: Claude | J8: qa/Claude (see RERUN_SUMMARY.md, verification/, review/PEER_REVIEW.md) | L8: 33c6c47068df10f5f7cb56c8bf3c00cdd210a50d (merge of PR #28).
A9: A4 | B9: Setup and independence | C9: Install the software exactly as instructed | D9: Follow start-here/README.md steps 1 to 5 without changes. Note any step you had to change or that was unclear. | E9: start-here/README.md, steps 1-5 | F9: Setup ends with 'Successfully installed'; deviations noted | G9: Pass | H9: 2026-10-21 | I9: Claude | J9: qa/Claude (see RERUN_SUMMARY.md, verification/, review/PEER_REVIEW.md) | L9: Followed steps 1-5 as written; no deviations. One pip "new release available" notice.
A10: A5 | B10: Setup and independence | C10: Confirm the pinned DuckDB version | D10: Run .venv/bin/python -c "import duckdb; print(duckdb.__version__)" | E10: pyproject.toml; requirements.txt | F10: 1.5.6 (random draws depend on this version) | G10: Pass | H10: 2026-10-21 | I10: Claude | J10: qa/Claude (see RERUN_SUMMARY.md, verification/, review/PEER_REVIEW.md) | L10: 1.5.6
A11: B. Re-run with date-stamped logs
A12: B1 | B12: Re-run with date-stamped logs | C12: Run the quick trial | D12: Run .venv/bin/python start-here/run_all.py --quick and record the log folder name. | E12: start-here/logs/run_<date>_<time>_quick/ | F12: Ends with 'Your setup works.' | G12: Pass | H12: 2026-10-21 | I12: Claude | J12: qa/Claude (see RERUN_SUMMARY.md, verification/, review/PEER_REVIEW.md) | L12: logs/run_2026-10-21_145457_quick: ends "Your setup works." (2m 28s).
A13: B2 | B13: Re-run with date-stamped logs | C13: Start the full replication and record the start date and time | D13: Run .venv/bin/python start-here/run_all.py . Record the start time on the Run log sheet. | E13: start-here/logs/run_<date>_<time>/run_log.txt (first line) | F13: Run started; log folder created | G13: Pass | H13: 2026-10-21 | I13: Claude | J13: qa/Claude (see RERUN_SUMMARY.md, verification/, review/PEER_REVIEW.md) | L13: logs/run_2026-10-21_145729/run_log.txt first line 2026-10-21 14:57:29.
A14: B3 | B14: Re-run with date-stamped logs | C14: Stage 1 completed: populations built and calibration checks passed | D14: In run_log.txt, find 'Stage 1 finished'. Open each errors/output*/.../checks.json and confirm every check passes. | E14: run_log.txt; */errors/output*/*/checks.json | F14: Stage 1 finished; all calibration checks pass | G14: Pass | H14: 2026-10-21 | I14: Claude | J14: qa/Claude (see RERUN_SUMMARY.md, verification/, review/PEER_REVIEW.md) | L14: Stage 1 finished in 1m 17s. All checks.json entries pass (Part D entries marked "reported, not a target" are informational).
A15: B4 | B15: Re-run with date-stamped logs | C15: Stage 2 completed: reported estimates (parametric-rate bootstrap) | D15: Find 'Stage 2 finished' in run_log.txt. Record the time on the Run log sheet. | E15: run_log.txt; */estimation/results/ | F15: Stage 2 finished, no FAILED lines | G15: Pass | H15: 2026-10-21 | I15: Claude | J15: qa/Claude (see RERUN_SUMMARY.md, verification/, review/PEER_REVIEW.md) | L15: Stage 2 finished in 1h 05m 15s (published 1h 08m 24s).
A16: B5 | B16: Re-run with date-stamped logs | C16: Stage 3 completed: fixed-rate comparison | D16: Find 'Stage 3 finished' in run_log.txt. | E16: run_log.txt; */estimation/results_fixed/ | F16: Stage 3 finished, no FAILED lines | G16: Pass | H16: 2026-10-21 | I16: Claude | J16: qa/Claude (see RERUN_SUMMARY.md, verification/, review/PEER_REVIEW.md) | L16: Stage 3 finished in 1h 02m 59s in the resumed run (run_2026-10-21_165745).
A17: B6 | B17: Re-run with date-stamped logs | C17: Stage 4 completed: Part D pre-IRA reference | D17: Find 'Stage 4 finished' in run_log.txt. | E17: run_log.txt; part-d-ipm/pre-ira-reference.md | F17: Stage 4 finished, no FAILED lines | G17: Pass | H17: 2026-10-21 | I17: Claude | J17: qa/Claude (see RERUN_SUMMARY.md, verification/, review/PEER_REVIEW.md) | L17: Stage 4 finished in 58m 23s (run_2026-10-21_180449).
A18: B7 | B18: Re-run with date-stamped logs | C18: Stages 5 and 6 completed: report and manuscript tables | D18: Find 'Stage 5 finished' and 'Stage 6 finished' in run_log.txt. | E18: run_log.txt; shared/results/report/; manuscripts/generated/ | F18: Both stages finished | G18: Pass | H18: 2026-10-21 | I18: Claude | J18: qa/Claude (see RERUN_SUMMARY.md, verification/, review/PEER_REVIEW.md) | L18: Stages 5 and 6 finished (1s, 4s).
A19: B8 | B19: Re-run with date-stamped logs | C19: Stage 7 completed: automated tests pass | D19: Open the stage7 log. The last pytest line reports the number passed. | E19: start-here/logs/run_*/stage7_01_pytest.log | F19: All tests passed, 0 failed | G19: Pass | H19: 2026-10-21 | I19: Claude | J19: qa/Claude (see RERUN_SUMMARY.md, verification/, review/PEER_REVIEW.md) | L19: stage7_01_pytest.log: 38 passed in 59.00s.
A20: B9 | B20: Re-run with date-stamped logs | C20: Stage 8: the result check reproduces the published results | D20: Open the stage8 log (or verification/verify_check.txt after collecting). | E20: start-here/logs/run_*/stage8_01_start_here_verify.log | F20: REPRODUCED EXACTLY (or REPRODUCED, with the reason explained in Notes) | G20: Pass | H20: 2026-10-21 | I20: Claude | J20: qa/Claude (see RERUN_SUMMARY.md, verification/, review/PEER_REVIEW.md) | L20: REPRODUCED EXACTLY: 183 of 183 output files byte-for-byte identical.
A21: B10 | B21: Re-run with date-stamped logs | C21: If the run was interrupted, every stage still completed once | D21: If you resumed with --from, confirm that each stage 1-8 has a 'Stage N finished' line across the run folders. | E21: start-here/logs/run_*/run_log.txt | F21: Every stage finished at least once, in order; or N/A | G21: Pass | H21: 2026-10-21 | I21: Claude | J21: qa/Claude (see RERUN_SUMMARY.md, verification/, review/PEER_REVIEW.md) | L21: The first full run was stopped by the reviewer's own process time limit during stage 3 (CERT fixed-rate). Resumed with --only 3 then --from 4; every stage finished once, in order, across the three run folders.
A22: B11 | B22: Re-run with date-stamped logs | C22: The logs contain no errors | D22: Search every .log file for 'Traceback', 'Error', 'FAILED' and 'exit code: 1'. (A RuntimeWarning is not an error.) | E22: start-here/logs/run_*/*.log | F22: None found, or each explained in Notes | G22: Pass | H22: 2026-10-21 | I22: Claude | J22: qa/Claude (see RERUN_SUMMARY.md, verification/, review/PEER_REVIEW.md) | L22: No Traceback, FAILED or exit code: 1 in any .log.
A23: B12 | B23: Re-run with date-stamped logs | C23: Collect the re-run into the QA holding space | D23: Run .venv/bin/python qa/collect_rerun.py --reviewer "Your Name" --initials XX | E23: qa/reruns/<date>_<initials>/ | F23: Folder created; RERUN_SUMMARY.md lists your runs and the result check | G23: Pass | H23: 2026-10-21 | I23: Claude | J23: qa/Claude (see RERUN_SUMMARY.md, verification/, review/PEER_REVIEW.md) | L23: Collected as qa/reruns/2026-10-21_CLAUDE then moved to qa/Claude per the author's instruction.
... A25: B14 | B25: Re-run with date-stamped logs | C25: Review the file inventory | D25: Open file_inventory.csv in Excel. Filter matches_published for 'NO'. | E25: qa/reruns/<date>_<initials>/verification/file_inventory.csv | F25: No rows with 'NO', or each explained in Notes | G25: Pass | H25: 2026-10-21 | I25: Claude | J25: qa/Claude (see RERUN_SUMMARY.md, verification/, review/PEER_REVIEW.md) | L25: file_inventory.csv: 0 rows with NO.
A26: C. Code review: key assumptions
A27: C1 | B27: Code review: key assumptions | C27: Review is perfect: the audit finding equals the true error | D27: Confirm that the sampled units' y is read directly from the population's true y, with no review error or appeals. | E27: shared/sql/sample_srs.sql; shared/sql/sample_systematic.sql; */estimation/sql/*01_frame.sql | F27: Sample y = population y; no reviewer error modeled (manuscript Appendix B.6, item 1) | G27: Pass | H27: 2026-10-21 | I27: Claude | J27: qa/Claude (see RERUN_SUMMARY.md, verification/, review/PEER_REVIEW.md) | L27: sample_srs.sql / sample_systematic.sql read y from the population; no review error modeled.
A28: C2 | B28: Code review: key assumptions | C28: One audit per audit year; every method uses only that audit | D28: Confirm that expansion, ratio and regression read the same sample table, and that the bootstrap simulation uses only that year's audit findings (Part D: its own 5,000-PDE audit). | E28: */estimation/config.yaml (step order); shared/ipsim/simulation.py | F28: No method sees the population's true errors; Part D's two audits are as documented | G28: Pass | H28: 2026-10-21 | I28: Claude | J28: qa/Claude (see RERUN_SUMMARY.md, verification/, review/PEER_REVIEW.md) | L28: All analytic methods read the same sample table; simulation uses only that year's audit. Note README.md:14 wrongly describes a 108,000-beneficiary sample (I-08).
A29: C3 | B29: Code review: key assumptions | C29: Errors are independent of selection within a stratum | D29: Confirm that errors are fabricated before sampling and that sample selection uses only stratum and unit id (not y). | E29: */errors/sql/*apply_errors*.sql; shared/sql/sample_srs.sql; shared/sql/lib/00_rng.sql | F29: Selection keys never use y | G29: Pass | H29: 2026-10-21 | I29: Claude | J29: qa/Claude (see RERUN_SUMMARY.md, verification/, review/PEER_REVIEW.md) | L29: Selection keys use only seed/stream/stratum/unit id.
A30: C4 | B30: Code review: key assumptions | C30: Neyman allocation uses the population's stratum standard deviations | D30: Confirm n_h is proportional to N_h x S_h, with S_h computed from the population (standing in for prior-year data), and sums to the stated audit size. | E30: eipm/estimation/sql/01_frame.sql; perm-cert/estimation/sql/perm_01_frame.sql, cert_01_frame.sql; part-d-ipm/estimation/sql/40_simulation_inputs.sql; allocation.json | F30: Neyman formula; sizes 2,000 (EIPM), 520 per state (PERM), 37,651 (CERT), 5,000 PDEs (Part D) | G30: Pass | H30: 2026-10-21 | I30: Claude | J30: qa/Claude (see RERUN_SUMMARY.md, verification/, review/PEER_REVIEW.md) | L30: Neyman n_h ∝ N_h S_h with S_h from the population; sizes 2,000 / 520 / 37,651 / 5,000 confirmed. Part D lowest-decile stratum receives n_h ≈ 4.
A31: C5 | B31: Code review: key assumptions | C31: Netting: errors netted within the payment unit before measures | D31: Confirm over = sum max(y,0), under = sum max(-y,0), gross = over + under, net = over - under, after netting per enrollee/beneficiary/claim. | E31: */estimation/sql/*01_frame.sql; */errors/sql/*truth*.sql | F31: Matches manuscript Section 3.3 | G31: Pass | H31: 2026-10-21 | I31: Claude | J31: qa/Claude (see RERUN_SUMMARY.md, verification/, review/PEER_REVIEW.md) | L31: Netting as stated in the population and analytic estimators.
A32: C6 | B32: Code review: key assumptions | C32: Unknown payments (e.g., missing documentation) count as improper | D32: Confirm missing-documentation errors set the whole payment (or every HCC) to improper. | E32: part-c-ipm/errors/sql/04_apply_errors.sql; perm-cert/errors/sql/cert_02_apply_errors.sql | F32: Follows CMS practice (Appendix B.6, item 6) | G32: Pass | H32: 2026-10-21 | I32: Claude | J32: qa/Claude (see RERUN_SUMMARY.md, verification/, review/PEER_REVIEW.md) | L32: Missing documentation loses every HCC (Part C); no/insufficient documentation = whole claim (CERT).
A33: C7 | B33: Code review: key assumptions | C33: Calibration is one closed-form multiplier, with no iterative tuning | D33: Confirm each calibrated rate = base probability x (target dollars / expected dollars), and that the multiplier is logged. | E33: */errors/sql/*apply_errors*.sql; part-d-ipm/errors/sql/03_init_calibration.sql; truth.json (by.calibration) | F33: One multiplier per target; recorded in truth.json | G33: Pass | H33: 2026-10-21 | I33: Claude | J33: qa/Claude (see RERUN_SUMMARY.md, verification/, review/PEER_REVIEW.md) | L33: One closed-form multiplier per target; logged in truth.json.
A34: C8 | B34: Code review: key assumptions | C34: Random draws are deterministic functions of (seed, stream, key) | D34: Confirm SQL draws hash a single string per stream and simulation draws use PCG64 seeded by SeedSequence([scenario seed, audit year]). | E34: shared/sql/lib/00_rng.sql; shared/ipsim/engine.py (child_seed); shared/ipsim/simulation.py | F34: No unseeded randomness anywhere | G34: Pass | H34: 2026-10-21 | I34: Claude | J34: qa/Claude (see RERUN_SUMMARY.md, verification/, review/PEER_REVIEW.md) | L34: hash(seed,stream,key) in SQL; PCG64 via SeedSequence([seed, audit year]) in simulation.
A35: C9 | B35: Code review: key assumptions | C35: Scale factors convert synthetic units to national dollars | D35: Confirm w_pop: Part C 100, Part D 500, EIPM 100, PERM 200, CERT 200; national dollars = rate x total payments x w_pop. | E35: */errors/config.yaml (w_pop); shared/sql/report.sql | F35: Values as stated; rates are scale-free | G35: Pass | H35: 2026-10-21 | I35: Claude | J35: qa/Claude (see RERUN_SUMMARY.md, verification/, review/PEER_REVIEW.md) | L35: w_pop 100/500/100/200/200 in configs; report.sql duplicates the values (agree).
A36: C10 | B36: Code review: key assumptions | C36: Analytic intervals: normal (1.96) with finite population correction | D36: Confirm expansion and ratio variances use the stratified SRS formula with (1 - n_h/N_h), and intervals are estimate +/- 1.96 SE. | E36: shared/sql/lib/02_estimators.sql (ipm_expansion, ipm_ratio) | F36: Matches manuscript Section 3.4 | G36: Pass | H36: 2026-10-21 | I36: Claude | J36: qa/Claude (see RERUN_SUMMARY.md, verification/, review/PEER_REVIEW.md) | L36: Verified against an independent per-unit numpy reference and against the exact design SE from the population (Part C ratio 54.65 vs 54.85 bp).
A37: C11 | B37: Code review: key assumptions | C37: Regression: models fit within strata; residual t interval | D37: Confirm design-weighted least squares within each model stratum, T = sum of predictions + weighted residuals, variance from residuals, t with df = n - strata - terms. | E37: shared/ipsim/regression.py; */estimation/sql/*30_regression.sql | F37: Matches manuscript Section 3.4 | G37: Fail | H37: 2026-10-21 | I37: Claude | J37: qa/Claude (see RERUN_SUMMARY.md, verification/, review/PEER_REVIEW.md) | K37: I-07 | L37: df subtracts intercepts twice (regression.py:110); negligible at n=990
A38: C12 | B38: Code review: key assumptions | C38: Regression fallback: intercept-only with too few errors | D38: Confirm a stratum uses an intercept-only model when it has fewer than 10 audited errors or fewer than (terms + 5) units. | E38: shared/ipsim/regression.py; */estimation/config.yaml (reg_min_errors: 10) | F38: Threshold 10 errors; terms + 5 units | G38: Fail | H38: 2026-10-21 | I38: Claude | J38: qa/Claude (see RERUN_SUMMARY.md, verification/, review/PEER_REVIEW.md) | K38: I-07 | L38: fallback counts audited errors in any domain, not the domain estimated (regression.py:82)
A39: C13 | B39: Code review: key assumptions | C39: Regression predictors by program | D39: Confirm reg_predictors: Part C x, demo_score, months, n_hcc; Part D x, gdc_sub, n_pde, catastrophic (post-strata LTC/LIS/other); EIPM x, age, hh_size, fpl_pct, months; PERM x, month, bene_n_pay, bene_paid; CERT x. | E39: */estimation/config.yaml; perm-cert/estimation/perm.yaml, cert.yaml | F39: Predictors as listed in manuscript Section 3.4 | G39: Pass | H39: 2026-10-21 | I39: Claude | J39: qa/Claude (see RERUN_SUMMARY.md, verification/, review/PEER_REVIEW.md) | L39: Predictors as listed.
A40: C14 | B40: Code review: key assumptions | C40: Bootstrap simulation (fixed rates): p = f/n, q = g/f per donor kind | D40: Confirm each non-audited unit is in error with p_k, partial with q_k, partial size drawn uniformly from the audited partial sizes. | E40: shared/ipsim/simulation.py; */estimation/*simulation.py; */estimation/sql/*40_simulation_inputs.sql | F40: Matches manuscript Section 3.5 | G40: Fail | H40: 2026-10-21 | I40: Claude | J40: qa/Claude (see RERUN_SUMMARY.md, verification/, review/PEER_REVIEW.md) | K40: I-10 | L40: Part C kernel uses the HCC mean audited loss, not a uniform draw from the partial list (simulation.py:104,133); §3.5/A.5 say "drawn uniformly"
A41: C15 | B41: Code review: key assumptions | C41: Bootstrap simulation (parametric rates): binomial redraw each iteration | D41: Confirm p~ = Binomial(n, p)/n and q~ = Binomial(f, q)/f before every iteration, and that zero-failure rates stay at zero. | E41: shared/ipsim/simulation.py (sim_rates: parametric) | F41: Matches manuscript Section 3.6 | G41: Fail | H41: 2026-10-21 | I41: Claude | J41: qa/Claude (see RERUN_SUMMARY.md, verification/, review/PEER_REVIEW.md) | K41: I-06 | L41: q~ is drawn as Binomial(f, q)/f with the observed f rather than the redrawn f~ (part-d simulation.py:204; perm_simulation.py:94; cert_simulation.py:197). Zero-failure rates stay at zero: confirmed.
A42: C16 | B42: Code review: key assumptions | C42: Audited units keep their own findings | D42: Confirm the simulation assigns errors only to non-audited units and keeps each audited unit's actual finding. | E42: */estimation/*simulation.py | F42: Audited units unchanged across iterations | G42: Fail | H42: 2026-10-21 | I42: Claude | J42: qa/Claude (see RERUN_SUMMARY.md, verification/, review/PEER_REVIEW.md) | K42: I-02 | L42: Audited units keep findings (confirmed), but non-audited Part C recipients receive additions independently of failures and the two are netted; the population never co-generates them (04_apply_errors.sql:125). Simulated under runs ~8% low.
...

Sheet Run log
A1: Run log
A2: One row per run folder in start-here/logs/ (copy from RERUN_SUMMARY.md and run_log.txt). Duration is calculated.
A4: Run folder name | B4: Run type | C4: Stages run | D4: Started (YYYY-MM-DD HH:MM) | E4: Finished (YYYY-MM-DD HH:MM) | F4: Duration (h:mm) | G4: Outcome | H4: Result check | I4: Notes
A5: run_2026-10-21_145457_quick | B5: Quick trial | C5: 1-2 | D5: 2026-10-21 14:54 | E5: 2026-10-21 14:57 | F5: =IF(AND(ISNUMBER(D5),ISNUMBER(E5)),E5-D5,"") | G5: Finished | H5: N/A (trial) | I5: Your setup works.
A6: run_2026-10-21_145729 | B6: Full replication | C6: 1-3 (interrupted) | D6: 2026-10-21 14:57 | E6: 2026-10-21 16:57 | F6: =IF(AND(ISNUMBER(D6),ISNUMBER(E6)),E6-D6,"") | G6: Interrupted in stage 3 | H6: n/a | I6: Stopped by the reviewer's background-process time limit during CERT fixed-rate run
A7: run_2026-10-21_165745 | B7: Full replication (resumed) | C7: 3 | D7: 2026-10-21 16:57 | E7: 2026-10-21 18:00 | F7: =IF(AND(ISNUMBER(D7),ISNUMBER(E7)),E7-D7,"") | G7: Finished | H7: n/a | I7: --only 3
A8: run_2026-10-21_180449 | B8: Full replication (resumed) | C8: 4-8 | D8: 2026-10-21 18:04 | E8: 2026-10-21 19:04 | F8: =IF(AND(ISNUMBER(D8),ISNUMBER(E8)),E8-D8,"") | G8: Finished | H8: REPRODUCED EXACTLY | I8: --from 4; 183/183 files identical; 38 tests passed
F9: =IF(AND(ISNUMBER(D9),ISNUMBER(E9)),E9-D9,"")
F10: =IF(AND(ISNUMBER(D10),ISNUMBER(E10)),E10-D10,"")
F11: =IF(AND(ISNUMBER(D11),ISNUMBER(E11)),E11-D11,"")
F12: =IF(AND(ISNUMBER(D12),ISNUMBER(E12)),E12-D12,"")
F13: =IF(AND(ISNUMBER(D13),ISNUMBER(E13)),E13-D13,"")
F14: =IF(AND(ISNUMBER(D14),ISNUMBER(E14)),E14-D14,"")
F15: =IF(AND(ISNUMBER(D15),ISNUMBER(E15)),E15-D15,"")
F16: =IF(AND(ISNUMBER(D16),ISNUMBER(E16)),E16-D16,"")
A19: Stage run times (full replication)
A20: Stage | B20: Description | D20: Published time (2 cores, 8 GB) | E20: Your time (h:mm:ss) | G20: Notes
A21: 1 | B21: Build the synthetic populations | D21: 0.0008912037 | E21: 0:01:17
A22: 2 | B22: Estimate: parametric-rate bootstrap (reported) | D22: 0.0475 | E22: 1:05:15
A23: 3 | B23: Estimate: fixed-rate bootstrap (comparison) | D23: 0.050219907 | E23: 1:02:59
A24: 4 | B24: Part D pre-IRA reference | D24: 0.047835648 | E24: 0:58:23
A25: 5 | B25: Join estimates to the truth | D25: 1.1574074e-05 | E25: 0:00:01
A26: 6 | B26: Manuscript tables and figures | D26: 2.3148148e-05 | E26: 0:00:04
A27: 7 | B27: Automated tests | D27: 0.00071759259 | E27: 0:01:00
A28: 8 | B28: Result check | D28: 1.1574074e-05 | E28: 0:00:03
B29: Total | D29: =SUM(D21:D28) | E29: =SUM(E21:E28)
A30: Published times: measured on the author's test re-run, 2026-10-20 (start-here/README.md, step 7). Enter your times from run_log.txt ('Stage N finished in ...').

Sheet Issues log
A1: Issues log
A2: One row per problem found. Use the ID (I-01, I-02, ...) in the Checklist's Issue ID column.
A4: Issue ID | B4: Date found | C4: Checklist ID | D4: Severity | E4: Description | F4: File / location | G4: How found | H4: Status | I4: Resolution | J4: Date resolved | K4: Resolved by
A5: I-01 | B5: 2026-10-21 | C5: C21 | D5: Minor | E5: Part C errors/config.yaml design block lists 1,500 enrollees per stratum; the estimation uses 330 per tercile (990). Confirmed. | F5: part-c-ipm/errors/config.yaml:39-42 | G5: Code review | H5: Open | I5: Metadata only; correct the description.
A6: I-02 | B6: 2026-10-21 | C6: C16 | D6: Major | E6: Part C simulation kernel applies audited addition rates to recipients that also received HCC failures in the iteration and nets the two; the population applies additions only when no overpayment and no missing documentation. Simulated underpayments run ~8% below the kernel's linear expectation (committed mean 49.3 bp vs truth 57.4; analytic 54-55); over and gross biased down ~0.8% / 1.5%. | F6: part-c-ipm/estimation/simulation.py:137-143 vs errors/sql/04_apply_errors.sql:125 | G6: Code review + standalone check (review/scripts/agent_b/q8.py) | H6: Open | I6: Apply additions only to recipients with no failure, or redefine the addition-rate denominator; add per-domain unbiasedness test; re-run Part C.
A7: I-03 | B7: 2026-10-21 | C7: C37, D14 | D7: Major | E7: Approximate Monte Carlo over 2,000 Part C and 300 EIPM re-drawn audits: the true SD of the simulation's (linearized) point estimator is 50.8 bp (Part C) / 17.8 bp (EIPM) vs reported parametric SE 47.2 / 16.1, while the ratio SE matches its exact design SE. Parametric interval ~7-10% too narrow for its own estimator; implies ~92-93% coverage, indistinguishable from 95% with 25 audit years; audit-size shares would be ~86% / 92% not 79% / 80%. | F7: part-c-ipm/estimation/simulation.py:104,126-133; eipm/estimation/simulation.py:94,114 | G7: Standalone check (review/scripts/agent_b/q7.py, q9.py) | H7: Open | I7: Run ≥200 audit years and report half-width ÷ (1.96 × empirical SD) and coverage with Monte Carlo SE; consider resampling error sizes and modeling rate correlation.
A8: I-04 | B8: 2026-10-21 | C8: D14 | D8: Major | E8: The simulation's width and point-accuracy advantage depends on error probability and size being independent of payment within strata, which is true by construction in every population; the simulation borrows count rates and takes sizes from the population while the analytic estimators are dollar-weighted. Explains the Part D 5x point-SD gap (specialty PDEs are 31-33% of error dollars). | F8: */errors/sql/*apply_errors*.sql (e.g. part-d 04_apply_errors.sql:8; cert_02_apply_errors.sql:18) | G8: Code review + standalone check (review/scripts/agent_c/q2.py) | H8: Open | I8: Add a robustness scenario (payment-dependent error probability, size-correlated taints, optional clustering) as a sub-folder and Appendix D; state the assumption for all programs in B.6.3; present the gain as model-based.
A9: I-05 | B9: 2026-10-21 | C9: C26, D14 | D9: Major | E9: Part D has no fair same-audit analytic comparator: ratio/regression use a 990-beneficiary audit that reviews ~41,000 PDEs; the PDE-audit "expansion" is a uniform-haircut plug-in whose delta-method SE understates its own SD (0.37 vs 0.54 pts). §4.1 and §4.3 misdescribe the cause of its bias and the width of its interval. | F9: part-d-ipm/estimation/simulation.py:227-253 | G9: Code review | H9: Open | I9: Implement a PDE-level HT/ratio comparator using each audited PDE's marginal Medicare-payment effect, or remove the Part D width comparison (63% / 37%) from the Abstract and Conclusion.
A10: I-06 | B10: 2026-10-21 | C10: C15 | D10: Minor | E10: Parametric redraw draws q~ = Binomial(f,q)/f with the observed f rather than the redrawn f~. | F10: part-d simulation.py:204; perm_simulation.py:94; cert_simulation.py:197 | G10: Code review | H10: Open | I10: Draw f~ first, or restate §3.6 as conditional on observed f.
A11: I-07 | B11: 2026-10-21 | C11: C11, C12 | D11: Minor | E11: Regression df subtracts intercepts twice (negligible at n=990); the <10-errors fallback counts errors in any domain, not the domain being estimated. | F11: shared/ipsim/regression.py:82,92,110 | G11: Code review | H11: Open | I11: df = n − terms; count errors per domain or document the rule as implemented.
A12: I-08 | B12: 2026-10-21 | C12: C2 | D12: Minor | E12: README.md:14 describes a "beneficiary sample (108,000 beneficiaries)" (the population) and says the simulation fixes a beneficiary sample; simulation.py docstring says the same. Code: SRS of 990 for ratio/regression; simulation uses the PDE audit only. | F12: README.md:14; shared/ipsim/simulation.py:27-28 | G12: Code review | H12: Open | I12: Correct both.
A13: I-09 | B13: 2026-10-21 | C13: C30, G4 | D13: Minor | E13: PERM documentation (README:17, perm.yaml:46 "equal across quarters and strata", perm_01_population.sql header, data_dictionary.md:110) describes equal-dollar strata within state × quarter × type; code builds equal-count quintiles within state × type, no quarter, Neyman. Also README:40 attributes the systematic-as-SRS variance note to CERT. | F13: perm-cert/README.md:17,40; perm-cert/errors/perm.yaml:46; shared/data_dictionary.md:110 | G13: Code review | H13: Open | I13: Align docs with code (design.yaml is written from perm.yaml:design).
A14: I-10 | B14: 2026-10-21 | C14: C14, C22 | D14: Minor | E14: Manuscript §3.5 step 2, §3.6 and A.5 step 4 say partial sizes are drawn uniformly from the audited list; the Part C kernel applies the HCC mean audited loss (B.1 says so). §5.3 "two binomial draws per stratum" is 30 draws per iteration in Part C. §3.5 "equivalent to a uniformly drawn donor" does not hold for Part C. | F14: part-c-ipm/estimation/simulation.py:104,133; manuscript §3.5, §3.6, §5.3, A.5 | G14: Code review | H14: Open | I14: Correct the method sections.
A15: I-11 | B15: 2026-10-21 | C15: D15, C23, C24 | D15: Minor | E15: Assumptions in code not stated: error independence from payment applies to Part C and Part D (B.6.3); Part D strata/sizes are illustrative (§3.2); all LIS pay $4.90/$12.15; MDP affects plan liability only; brand/specialty independent; direct subsidy constant; PERM whole-year eligibility propagated by the simulation; one FMAP per state; CERT error independent of stratum; underpayments all partial; Part C addition rule, hierarchy-move share, chart-review multiplier, coding intensity, probability cap; EIPM population and income-ratio rules. Full list in review/PEER_REVIEW.md Part 2.4. | F15: Appendix B | G15: Code review | H15: Open | I15: Add to Appendix B.
A16: I-12 | B16: 2026-10-21 | C16: F3 | D16: Minor | E16: References: ED OIG "FY 2025" report is the FY 2024 report (A25DC0225); FY 2025 is A26DC0288 (2026). "Humana v. Becerra, 801 F. Supp. 3d 624" reporter cite unverified. CMS 2025a fact sheet is dated Jan 15, 2026. GAO 2026 needs its number (GAO-26-108694). Orphans: Biddle 1990, Davison & Hinkley 1997, King & Madansky 2013, Rao & Wu 1988, Wolter 2007, CMS 2025d/2026a/2026b/2024. Missing entry for P.L. 119-21. §1.3 cross-reference should be §4.2. Secondary sources (MyChesCo, Milliman, STAT, BPC, conference bio) where primary exist. Several characterizations of Edwards et al. 2023, Kvanli & Schauer, Kolenikov and Liu 2025 over-read (details in review/review_citations.md). | F16: manuscript References; literature review §3-§6 and References | G16: Citation verification (web) | H16: Open | I16: Apply corrections in review/PEER_REVIEW.md Part 1.3.
... A23: I-19 | B23: 2026-10-21 | C23: F4 | D23: Minor | E23: Affiliation, funding, conflicts of interest and disclaimer are bracketed placeholders; employer/agency clearance not recorded. | F23: manuscripts/sections/00_front.md, 03_future_conclusion_refs.md | G23: Review | H23: Open | I23: Complete before circulation.
A41: Severity: Critical = a reported result is wrong or cannot be reproduced. Major = an assumption or method differs from its description in a way that could change a result. Minor = documentation or labeling error with no effect on results. Note = suggestion. Status 'Accepted' = left open by agreement, explained in Resolution. Row 5 is an example (a real discrepancy, also listed as Checklist C21). If you confirm it, delete '(EXAMPLE)' from its ID so it is counted; otherwise overwrite the row.
